Workbook

Sheet CAPA
A1: RELATÓRIO DE FOLHA PARA A CONTABILIDADE — LOJA TRANCOSO
A4: IDENTIFICAÇÃO
B5: Empresa: Farmácia Tropical Multi Econômica — loja TRANCOSO
B6: Competência (mês de referência): SETEMBRO/2026 — vendas de 01/09/2026 a 30/09/2026
B7: Data do pagamento: 05/10/2026
B8: Fonte das comissões e incentivos: InovaFarma — relatório de comissão de vendedor, a extrair no início de outubro/2026
B9: Funcionários: UILLIAN, MANOEL, VALDICK, INIURLE, TAMILES
A10: COMO USAR ESTE ARQUIVO
B11: 1. Abra a aba HOLERITE SET.26 — é o relatório que vai para a contabilidade.
B12: 2. Preencha as células AMARELAS (horas extras, prêmios, vales, convênio, faltas).
B13: 3. Confira as células LARANJAS — são valores repetidos de julho/2026 que podem ter mudado.
B14: 4. Comissões, incentivos e DSR já vêm calculados; não digite por cima.
B15: 5. A aba GANHOS DO COLABORADOR monta o demonstrativo individual: escolha o nome na lista.
B16: 6. INSS e IRRF ficam em branco: são calculados pela contabilidade.
A17: APURAÇÃO DO MÊS
B18: Venda bruta geral da loja: R$ 0,00 · descontos concedidos: R$ 0,00 · venda líquida: R$ 0,00
B19: Comissão apurada no InovaFarma: R$ 0,00 · incentivos: R$ 0,00
B20: DSR de setembro/2026: 4 domingos + os feriados de 07/09 e 08/09 (municipal) = 6 ÷ 24 dias úteis = fator 0,250000
A21: DEFINIÇÕES DA LOJA
B22: TRANCOSO PAGA O DOBRO DA COMISSÃO APURADA: a linha COMISSÃO PRODUTOS já multiplica por 2 o valor do InovaFarma.
B23: Os incentivos são simples: entram pelo valor apurado, sem dobrar.
B24: A diferença gerada pela comissão dobrada é reduzida nas premiações.
B25: UILLIAN: não recebe comissão sobre vendas.
B26: TAMILES: atestado de 02 a 08/09 abonado — salário integral, sem desconto.
B27: VALDICK: férias de 01 a 30/09/2026 (mês inteiro) — salário zerado; férias e 1/3 em recibo próprio.
A28: PENDÊNCIAS — CONFIRMAR ANTES DE ENVIAR
A29: • | B29: Horas extras, adicional noturno e feriados trabalhados de setembro — lançar na aba PONTO SET.26.
A30: • | B30: Prêmio cota geral e prêmio pré-vencidos, conforme a tabela de metas da loja.
A31: • | B31: Vales adiantados, convênio e faltas de agosto.
A32: • | B32: Férias, afastamentos e admissões que mudem o salário do mês.
A33: • | B33: Extrair o relatório de comissões de setembro no InovaFarma e preencher a aba BASE INOVAFARMA SET.26.
A34: • | B34: TAMILES: se o atestado for prorrogado além de 15 dias corridos, a partir do 16º dia passa a ser auxílio-doença do INSS.
A35: • | B35: Lançar na linha PRÊMIO COTA GERAL o valor já com a redução combinada.
A36: OBSERVAÇÃO TÉCNICA
B37: As células de total e de cálculo são fórmulas. Ao abrir no Excel ou no Google Planilhas elas aparecem calculadas; em visualizadores simples podem aparecer em branco até o arquivo ser aberto.
A38: ABAS DO ARQUIVO
B39: HOLERITE SET.26 — relatório principal da competência setembro/2026.
B40: GANHOS DO COLABORADOR — demonstrativo individual, pronto para imprimir/mandar.
B41: LISTA CONTABILIDADE — os mesmos lançamentos em formato de lista.
B42: BASE INOVAFARMA SET.26 — apuração de comissões e incentivos por vendedor.
...

Sheet PARÂMETROS
A1: PARÂMETROS DE CÁLCULO
A2: Farmácia Tropical Multi Econômica — loja TRANCOSO — competência SETEMBRO/2026
A4: COMPETÊNCIA / PAGAMENTO
A5: Competência (mês de referência) | B5: SETEMBRO/2026 | C5: Vendas de 01/09/2026 a 30/09/2026 (relatório InovaFarma).
A6: Data do pagamento | B6: 05/10/2026 | C6: Folha a ser lançada no holerite pago em 05/10/2026.
A7: Data de extração do InovaFarma | B7: a extrair | C7: Extrair o relatório da loja TRANCOSO no início de outubro/2026 e lançar na aba BASE INOVAFARMA SET.26.
A8: CALENDÁRIO DO MÊS (base do DSR)
A9: Dias do mês | B9: 30 | C9: Setembro/2026.
A10: Domingos + feriados | B10: 6 | C10: Domingos: 06, 13, 20 e 27/09/2026, mais os feriados de 07/09 (Independência, segunda) e 08/09 (municipal, terça).
A11: Dias úteis (inclui sábados) | B11: =B9-B10 | C11: Dias do mês menos domingos e feriados.
A12: Fator DSR (domingos ÷ dias úteis) | B12: =B10/B11 | C12: Domingos ÷ dias úteis. Usado na rubrica REPOUSO REMUNERADO / DSR.
A13: VALORES FIXOS / RECORRENTES
A14: Salário base (piso 2026) | B14: 1621 | C14: Valor praticado em ago/2026.
A15: Salário do gerente | B15: 5648.41 | C15: Conforme ago/2026.
A16: Horas mensais (base do salário-hora) | B16: 220 | C16: Salário-hora = salário base ÷ 220.
A17: Adicional de hora extra | B17: 0.5 | C17: 50% sobre a hora normal (hora extra = salário-hora × 1,5).
A18: Adicional noturno | B18: 0.2 | C18: 20% sobre a hora normal, nas horas entre 22h e 5h.
A19: Dias do mês para o salário-dia | B19: 30 | C19: Salário-dia = salário base ÷ 30. Usado no feriado trabalhado.
A20: Multiplicador da comissão | B20: 2 | C20: TRANCOSO paga o dobro do valor apurado no InovaFarma.
A21: INSS / IRRF
A22: INSS | B22: a calcular | C22: Calculado pela contabilidade sobre o total de proventos (tabela progressiva vigente).
A23: IRRF | B23: a calcular | C23: Calculado pela contabilidade após dedução do INSS e dependentes.

Sheet BASE INOVAFARMA SET.26
A1: APURAÇÃO DE COMISSÕES E INCENTIVOS — INOVAFARMA
A2: Loja TRANCOSO · vendas de 01/09/2026 a 30/09/2026 · PREENCHER com o relatório extraído no início de outubro
A4: CÓD. | B4: VENDEDOR | C4: VENDA BRUTA | D4: DESCONTOS | E4: VENDA LÍQUIDA | F4: COMISSÃO | G4: INCENT. APLIC. | H4: INCENT. VITAM. | I4: OUTROS INCENT. | J4: TOTAL INCENT.
A5: 13 | B5: UILLIAN | C5: 0 | D5: 0 | E5: 0 | F5: 0 | G5: 0 | H5: 0 | I5: 0 | J5: =SUM(G5:I5)
A6: 92 | B6: MANOEL | C6: 0 | D6: 0 | E6: 0 | F6: 0 | G6: 0 | H6: 0 | I6: 0 | J6: =SUM(G6:I6)
A7: 162 | B7: VALDICK | C7: 0 | D7: 0 | E7: 0 | F7: 0 | G7: 0 | H7: 0 | I7: 0 | J7: =SUM(G7:I7)
A8: 83 | B8: INIURLE | C8: 0 | D8: 0 | E8: 0 | F8: 0 | G8: 0 | H8: 0 | I8: 0 | J8: =SUM(G8:I8)
A9: 103 | B9: TAMILES | C9: 0 | D9: 0 | E9: 0 | F9: 0 | G9: 0 | H9: 0 | I9: 0 | J9: =SUM(G9:I9)
B10: TOTAL FUNCIONÁRIOS | C10: =SUM(C5:C9) | D10: =SUM(D5:D9) | E10: =SUM(E5:E9) | F10: =SUM(F5:F9) | G10: =SUM(G5:G9) | H10: =SUM(H5:H9) | I10: =SUM(I5:I9) | J10: =SUM(J5:J9)
A12: Códigos sem vínculo de folha nesta loja:
A14: CONFERÊNCIA — total geral do relatório: venda bruta R$ 0,00 · descontos R$ 0,00 · venda líquida R$ 0,00 · comissão R$ 0,00 · incentivo R$ 0,00,
A15: INCENT. APLIC. = incentivo do grupo INJETÁVEIS (aplicações). INCENT. VITAM. = grupo APLICAÇÃO E VITAMINAS INCENTIVO. OUTROS INCENT. = populares, oficinais e similar normal.
A16: PREENCHER esta aba com o relatório de comissões de setembro/2026, extraído do InovaFarma no início de outubro. Enquanto estiver zerada, o holerite fica só com salário e rubricas fixas.
A17: A comissão desta aba é a APURADA pelo sistema, sem multiplicador. O valor que vai para a folha está na aba HOLERITE SET.26.
A18: UILLIAN não recebe comissão em folha: no caso dele(a) a comissão apurada acima é apenas informativa.
A19: ATENÇÃO: nesta loja a comissão paga é o DOBRO do valor apurado acima.

Sheet HOLERITE SET.26
A1: RELATÓRIO PARA A CONTABILIDADE — LANÇAMENTO EM HOLERITE
A2: Loja TRANCOSO · competência SETEMBRO/2026 (01/08 a 31/08/2026) · pagamento em 05/09/2026
A4: RUBRICA | B4: UILLIAN | C4: MANOEL | D4: VALDICK | E4: INIURLE | F4: TAMILES | G4: TOTAL | H4: ORIGEM / OBSERVAÇÃO
A5: PROVENTOS
A6: SALÁRIO BASE | B6: 5648.41 | C6: 1621 | D6: 0 | E6: 1621 | F6: 1621 | G6: =SUM(B6:F6) | H6: Piso 2026 R$ 1.621,00; gerente conforme ago/2026. CONFERIR admissões, afastamentos e férias do mês.
A7: ADICIONAL NOTURNO | B7: =SUMIFS('PONTO SET.26'!$G$5:$G$14,'PONTO SET.26'!$A$5:$A$14,B$4,'PONTO SET.26'!$H$5:$H$14,"ADICIONAL NOTURNO") | C7: =SUMIFS('PONTO SET.26'!$G$5:$G$14,'PONTO SET.26'!$A$5:$A$14,C$4,'PONTO SET.26'!$H$5:$H$14,"ADICIONAL NOTURNO") | D7: =SUMIFS('PONTO SET.26'!$G$5:$G$14,'PONTO SET.26'!$A$5:$A$14,D$4,'PONTO SET.26'!$H$5:$H$14,"ADICIONAL NOTURNO") | E7: =SUMIFS('PONTO SET.26'!$G$5:$G$14,'PONTO SET.26'!$A$5:$A$14,E$4,'PONTO SET.26'!$H$5:$H$14,"ADICIONAL NOTURNO") | F7: =SUMIFS('PONTO SET.26'!$G$5:$G$14,'PONTO SET.26'!$A$5:$A$14,F$4,'PONTO SET.26'!$H$5:$H$14,"ADICIONAL NOTURNO") | G7: =SUM(B7:F7) | H7: Somado automaticamente da aba PONTO SET.26 (apontamento de setembro/2026). Para mudar, edite lá.
A8: HORAS EXTRAS | B8: =SUMIFS('PONTO SET.26'!$G$5:$G$14,'PONTO SET.26'!$A$5:$A$14,B$4,'PONTO SET.26'!$H$5:$H$14,"HORAS EXTRAS") | C8: =SUMIFS('PONTO SET.26'!$G$5:$G$14,'PONTO SET.26'!$A$5:$A$14,C$4,'PONTO SET.26'!$H$5:$H$14,"HORAS EXTRAS") | D8: =SUMIFS('PONTO SET.26'!$G$5:$G$14,'PONTO SET.26'!$A$5:$A$14,D$4,'PONTO SET.26'!$H$5:$H$14,"HORAS EXTRAS") | E8: =SUMIFS('PONTO SET.26'!$G$5:$G$14,'PONTO SET.26'!$A$5:$A$14,E$4,'PONTO SET.26'!$H$5:$H$14,"HORAS EXTRAS") | F8: =SUMIFS('PONTO SET.26'!$G$5:$G$14,'PONTO SET.26'!$A$5:$A$14,F$4,'PONTO SET.26'!$H$5:$H$14,"HORAS EXTRAS") | G8: =SUM(B8:F8) | H8: Somado automaticamente da aba PONTO SET.26 (apontamento de setembro/2026). Para mudar, edite lá.
A9: COMISSÃO PRODUTOS (INOVAFARMA) | B9: 0 | C9: =ROUND('BASE INOVAFARMA SET.26'!F6*PARÂMETROS!$B$20,2) | D9: =ROUND('BASE INOVAFARMA SET.26'!F7*PARÂMETROS!$B$20,2) | E9: =ROUND('BASE INOVAFARMA SET.26'!F8*PARÂMETROS!$B$20,2) | F9: =ROUND('BASE INOVAFARMA SET.26'!F9*PARÂMETROS!$B$20,2) | G9: =SUM(B9:F9) | H9: Apurado no InovaFarma (aba BASE INOVAFARMA SET.26), JÁ MULTIPLICADO POR 2 (multiplicador na aba PARÂMETROS). UILLIAN não recebe(m) comissão — lançado zero.
A10: COMPLEMENTO / COMISSÃO PDV | G10: =SUM(B10:F10) | H10: PREENCHER: PDV antigos e complementos de comissão acordados, se houver.
A11: COMISSÃO TOTAL (soma) | B11: =SUM(B9:B10) | C11: =SUM(C9:C10) | D11: =SUM(D9:D10) | E11: =SUM(E9:E10) | F11: =SUM(F9:F10) | G11: =SUM(B11:F11) | H11: Base do DSR junto com as horas extras.
A12: REPOUSO REMUNERADO / DSR | B12: =ROUND((B11+B8)*PARÂMETROS!$B$12,2) | C12: =ROUND((C11+C8)*PARÂMETROS!$B$12,2) | D12: =ROUND((D11+D8)*PARÂMETROS!$B$12,2) | E12: =ROUND((E11+E8)*PARÂMETROS!$B$12,2) | F12: =ROUND((F11+F8)*PARÂMETROS!$B$12,2) | G12: =SUM(B12:F12) | H12: Cálculo: (comissão total + horas extras) × (4 domingos + feriados de 07/09 e 08/09) ÷ 24 dias úteis de setembro/2026.
A13: AUXÍLIO GERÊNCIA | G13: =SUM(B13:F13) | H13: Conforme acordo da loja.
A14: ADICIONAL PRÊMIO META CAIXA | G14: =SUM(B14:F14) | H14: Conforme apuração do caixa.
A15: PRÊMIO COTA GERAL | G15: =SUM(B15:F15) | H15: PREENCHER conforme a tabela de metas da loja (aba METAS da planilha original). Lançar já com a redução combinada para compensar o aumento da comissão dobrada.
A16: PRÊMIO PRÉ-VENCIDOS | G16: =SUM(B16:F16) | H16: PREENCHER conforme a apuração de pré-vencidos de setembro.
A17: FÉRIAS (DIAS GOZADOS) | G17: =SUM(B17:F17) | H17: PREENCHER se houve férias no mês; informar o período.
A18: 1/3 CONSTITUCIONAL DE FÉRIAS | G18: =SUM(B18:F18) | H18: Calculado pela contabilidade sobre o valor das férias.
A19: INCENTIVO APLICAÇÕES | B19: ='BASE INOVAFARMA SET.26'!G5 | C19: ='BASE INOVAFARMA SET.26'!G6 | D19: ='BASE INOVAFARMA SET.26'!G7 | E19: ='BASE INOVAFARMA SET.26'!G8 | F19: ='BASE INOVAFARMA SET.26'!G9 | G19: =SUM(B19:F19) | H19: Incentivo de injetáveis apurado no InovaFarma. Incentivo é simples: NÃO entra em dobro.
A20: INCENTIVO VITAMINAS | B20: ='BASE INOVAFARMA SET.26'!H5 | C20: ='BASE INOVAFARMA SET.26'!H6 | D20: ='BASE INOVAFARMA SET.26'!H7 | E20: ='BASE INOVAFARMA SET.26'!H8 | F20: ='BASE INOVAFARMA SET.26'!H9 | G20: =SUM(B20:F20) | H20: Grupo APLICAÇÃO E VITAMINAS INCENTIVO no InovaFarma.
A21: OUTROS INCENTIVOS | B21: ='BASE INOVAFARMA SET.26'!I5 | C21: ='BASE INOVAFARMA SET.26'!I6 | D21: ='BASE INOVAFARMA SET.26'!I7 | E21: ='BASE INOVAFARMA SET.26'!I8 | F21: ='BASE INOVAFARMA SET.26'!I9 | G21: =SUM(B21:F21) | H21: Populares, oficinais e similar normal.
A22: TOTAL DE PROVENTOS | B22: =SUM(B6:B21)-B9-B10 | C22: =SUM(C6:C21)-C9-C10 | D22: =SUM(D6:D21)-D9-D10 | E22: =SUM(E6:E21)-E9-E10 | F22: =SUM(F6:F21)-F9-F10 | G22: =SUM(B22:F22) | H22: Soma das rubricas acima (a linha COMISSÃO TOTAL já engloba a comissão do InovaFarma e o complemento).
A23: DESCONTOS (lançar com sinal negativo)
A24: ADIANTAMENTO SALARIAL / VALES | G24: =SUM(B24:F24) | H24: PREENCHER com os vales adiantados durante setembro.
A25: ADIANT. VALES INCENT. E APLIC. | B25: =-(B19+B20+B21) | C25: =-(C19+C20+C21) | D25: =-(D19+D20+D21) | E25: =-(E19+E20+E21) | F25: =-(F19+F20+F21) | G25: =SUM(B25:F25) | H25: Estorno dos incentivos já adiantados em dinheiro no mês. AJUSTAR se algum incentivo não foi adiantado.
A26: CONVÊNIO | G26: =SUM(B26:F26) | H26: PREENCHER conforme o convênio de setembro.
A27: DESCONTO FALTAS / ATRASOS | G27: =SUM(B27:F27) | H27: PREENCHER conforme o ponto.
A28: DESCONTO VALE TRANSPORTE 6% | G28: =SUM(B28:F28) | H28: Valores praticados em ago/26. 6% sobre R$ 1.621,00 seria R$ 97,26 — CONFERIR a base usada.
A29: DESCONTO INSS | G29: =SUM(B29:F29) | H29: A CALCULAR PELA CONTABILIDADE sobre o total de proventos.
A30: DESCONTO IRRF | G30: =SUM(B30:F30) | H30: A CALCULAR PELA CONTABILIDADE.
A31: TOTAL DE DESCONTOS | B31: =SUM(B24:B30) | C31: =SUM(C24:C30) | D31: =SUM(D24:D30) | E31: =SUM(E24:E30) | F31: =SUM(F24:F30) | G31: =SUM(B31:F31)
A32: LÍQUIDO
A33: LÍQUIDO A RECEBER (05/10/2026) | B33: =B22+B31 | C33: =C22+C31 | D33: =D22+D31 | E33: =E22+E31 | F33: =F22+F31 | G33: =SUM(B33:F33) | H33: Total de proventos menos descontos. Só fica definitivo depois do INSS/IRRF da contabilidade.
A34: INFORMATIVO — PAGO PELA EMPRESA, NÃO ENTRA NO HOLERITE
A35: VALE TRANSPORTE (compra out/26) | G35: =SUM(B35:F35) | H35: PREENCHER com as passagens compradas.
A36: VALE ALIMENTAÇÃO FERIADOS E DOMINGOS | G36: =SUM(B36:F36) | H36: PREENCHER conforme escala de domingos e feriados.
A37: FÉRIAS PAGAS À PARTE (CONTAS A PAGAR) | G37: =SUM(B37:F37) | H37: Recibo de férias pago fora do holerite — lembrete para o contas a pagar. VALDICK: férias de 01 a 30/09/2026 — informar o valor do recibo.
A39: LEGENDA
A40: Célula amarela, texto azul | B40: valor digitado — PREENCHER ou conferir antes de enviar.
A41: Célula laranja | B41: valor repetido de agosto/2026 — CONFERIR se continua válido em setembro.
A42: Texto verde | B42: valor puxado da aba BASE INOVAFARMA SET.26 (não digitar por cima).
...

Sheet LISTA CONTABILIDADE
A1: LANÇAMENTOS POR FUNCIONÁRIO — TRANCOSO — SETEMBRO/2026 (pagamento 05/10/2026)
A2: Mesmos valores da aba HOLERITE SET.26, em formato de lista (vinculados por fórmula)
A4: FUNCIONÁRIO | B4: RUBRICA | C4: TIPO | D4: VALOR | E4: OBSERVAÇÃO
A5: UILLIAN | B5: SALÁRIO BASE | C5: Provento | D5: ='HOLERITE SET.26'!B6
A6: UILLIAN | B6: ADICIONAL NOTURNO | C6: Provento | D6: ='HOLERITE SET.26'!B7
A7: UILLIAN | B7: HORAS EXTRAS | C7: Provento | D7: ='HOLERITE SET.26'!B8
A8: UILLIAN | B8: COMISSÃO SOBRE VENDAS | C8: Provento | D8: ='HOLERITE SET.26'!B11
A9: UILLIAN | B9: REPOUSO REMUNERADO / DSR | C9: Provento | D9: ='HOLERITE SET.26'!B12
A10: UILLIAN | B10: AUXÍLIO GERÊNCIA | C10: Provento | D10: ='HOLERITE SET.26'!B13
A11: UILLIAN | B11: ADICIONAL PRÊMIO META CAIXA | C11: Provento | D11: ='HOLERITE SET.26'!B14
A12: UILLIAN | B12: PRÊMIO COTA GERAL | C12: Provento | D12: ='HOLERITE SET.26'!B15
A13: UILLIAN | B13: PRÊMIO PRÉ-VENCIDOS | C13: Provento | D13: ='HOLERITE SET.26'!B16
A14: UILLIAN | B14: FÉRIAS | C14: Provento | D14: ='HOLERITE SET.26'!B17
A15: UILLIAN | B15: 1/3 CONSTITUCIONAL DE FÉRIAS | C15: Provento | D15: ='HOLERITE SET.26'!B18
A16: UILLIAN | B16: INCENTIVO APLICAÇÕES | C16: Provento | D16: ='HOLERITE SET.26'!B19
A17: UILLIAN | B17: INCENTIVO VITAMINAS | C17: Provento | D17: ='HOLERITE SET.26'!B20
A18: UILLIAN | B18: OUTROS INCENTIVOS | C18: Provento | D18: ='HOLERITE SET.26'!B21
A19: UILLIAN | B19: TOTAL DE PROVENTOS | C19: Subtotal | D19: ='HOLERITE SET.26'!B22
A20: UILLIAN | B20: ADIANTAMENTO SALARIAL / VALES | C20: Desconto | D20: ='HOLERITE SET.26'!B24
A21: UILLIAN | B21: ADIANT. VALES INCENT. E APLIC. | C21: Desconto | D21: ='HOLERITE SET.26'!B25
A22: UILLIAN | B22: CONVÊNIO | C22: Desconto | D22: ='HOLERITE SET.26'!B26
A23: UILLIAN | B23: DESCONTO FALTAS / ATRASOS | C23: Desconto | D23: ='HOLERITE SET.26'!B27
A24: UILLIAN | B24: DESCONTO VALE TRANSPORTE 6% | C24: Desconto | D24: ='HOLERITE SET.26'!B28
A25: UILLIAN | B25: DESCONTO INSS | C25: Desconto | D25: ='HOLERITE SET.26'!B29
A26: UILLIAN | B26: DESCONTO IRRF | C26: Desconto | D26: ='HOLERITE SET.26'!B30
A27: UILLIAN | B27: TOTAL DE DESCONTOS | C27: Subtotal | D27: ='HOLERITE SET.26'!B31
A28: UILLIAN | B28: LÍQUIDO A RECEBER | C28: Líquido | D28: ='HOLERITE SET.26'!B33
A30: MANOEL | B30: SALÁRIO BASE | C30: Provento | D30: ='HOLERITE SET.26'!C6
A31: MANOEL | B31: ADICIONAL NOTURNO | C31: Provento | D31: ='HOLERITE SET.26'!C7
A32: MANOEL | B32: HORAS EXTRAS | C32: Provento | D32: ='HOLERITE SET.26'!C8
A33: MANOEL | B33: COMISSÃO SOBRE VENDAS | C33: Provento | D33: ='HOLERITE SET.26'!C11
A34: MANOEL | B34: REPOUSO REMUNERADO / DSR | C34: Provento | D34: ='HOLERITE SET.26'!C12
A35: MANOEL | B35: AUXÍLIO GERÊNCIA | C35: Provento | D35: ='HOLERITE SET.26'!C13
A36: MANOEL | B36: ADICIONAL PRÊMIO META CAIXA | C36: Provento | D36: ='HOLERITE SET.26'!C14
A37: MANOEL | B37: PRÊMIO COTA GERAL | C37: Provento | D37: ='HOLERITE SET.26'!C15
A38: MANOEL | B38: PRÊMIO PRÉ-VENCIDOS | C38: Provento | D38: ='HOLERITE SET.26'!C16
A39: MANOEL | B39: FÉRIAS | C39: Provento | D39: ='HOLERITE SET.26'!C17
A40: MANOEL | B40: 1/3 CONSTITUCIONAL DE FÉRIAS | C40: Provento | D40: ='HOLERITE SET.26'!C18
A41: MANOEL | B41: INCENTIVO APLICAÇÕES | C41: Provento | D41: ='HOLERITE SET.26'!C19
A42: MANOEL | B42: INCENTIVO VITAMINAS | C42: Provento | D42: ='HOLERITE SET.26'!C20
...

Sheet GANHOS DO COLABORADOR
A1: DEMONSTRATIVO DE GANHOS DO COLABORADOR
A2: Loja TRANCOSO · competência SETEMBRO/2026 · pagamento em 05/09/2026
B4: Escolha o colaborador: | C4: UILLIAN | D4: Troque o nome aqui e a tabela abaixo muda sozinha — é o relatório para mandar para cada um.
B6: PROVENTOS
B7: Salário base | C7: =IFERROR(INDEX('HOLERITE SET.26'!$B$6:$F$6,1,MATCH($C$4,'HOLERITE SET.26'!$B$4:$F$4,0)),0)
B8: Adicional noturno | C8: =IFERROR(INDEX('HOLERITE SET.26'!$B$7:$F$7,1,MATCH($C$4,'HOLERITE SET.26'!$B$4:$F$4,0)),0)
B9: Horas extras | C9: =IFERROR(INDEX('HOLERITE SET.26'!$B$8:$F$8,1,MATCH($C$4,'HOLERITE SET.26'!$B$4:$F$4,0)),0)
B10: Comissão sobre vendas | C10: =IFERROR(INDEX('HOLERITE SET.26'!$B$11:$F$11,1,MATCH($C$4,'HOLERITE SET.26'!$B$4:$F$4,0)),0)
B11: Repouso remunerado / DSR | C11: =IFERROR(INDEX('HOLERITE SET.26'!$B$12:$F$12,1,MATCH($C$4,'HOLERITE SET.26'!$B$4:$F$4,0)),0)
B12: Auxílio gerência | C12: =IFERROR(INDEX('HOLERITE SET.26'!$B$13:$F$13,1,MATCH($C$4,'HOLERITE SET.26'!$B$4:$F$4,0)),0)
B13: Adicional prêmio meta caixa | C13: =IFERROR(INDEX('HOLERITE SET.26'!$B$14:$F$14,1,MATCH($C$4,'HOLERITE SET.26'!$B$4:$F$4,0)),0)
B14: Prêmio cota geral | C14: =IFERROR(INDEX('HOLERITE SET.26'!$B$15:$F$15,1,MATCH($C$4,'HOLERITE SET.26'!$B$4:$F$4,0)),0)
B15: Prêmio pré-vencidos | C15: =IFERROR(INDEX('HOLERITE SET.26'!$B$16:$F$16,1,MATCH($C$4,'HOLERITE SET.26'!$B$4:$F$4,0)),0)
B16: Férias | C16: =IFERROR(INDEX('HOLERITE SET.26'!$B$17:$F$17,1,MATCH($C$4,'HOLERITE SET.26'!$B$4:$F$4,0)),0)
B17: 1/3 constitucional de férias | C17: =IFERROR(INDEX('HOLERITE SET.26'!$B$18:$F$18,1,MATCH($C$4,'HOLERITE SET.26'!$B$4:$F$4,0)),0)
B18: Incentivo aplicações | C18: =IFERROR(INDEX('HOLERITE SET.26'!$B$19:$F$19,1,MATCH($C$4,'HOLERITE SET.26'!$B$4:$F$4,0)),0)
B19: Incentivo vitaminas | C19: =IFERROR(INDEX('HOLERITE SET.26'!$B$20:$F$20,1,MATCH($C$4,'HOLERITE SET.26'!$B$4:$F$4,0)),0)
B20: Outros incentivos | C20: =IFERROR(INDEX('HOLERITE SET.26'!$B$21:$F$21,1,MATCH($C$4,'HOLERITE SET.26'!$B$4:$F$4,0)),0)
B21: TOTAL DE PROVENTOS | C21: =IFERROR(INDEX('HOLERITE SET.26'!$B$22:$F$22,1,MATCH($C$4,'HOLERITE SET.26'!$B$4:$F$4,0)),0)
B22: DESCONTOS
B23: Adiantamento salarial / vales | C23: =IFERROR(INDEX('HOLERITE SET.26'!$B$24:$F$24,1,MATCH($C$4,'HOLERITE SET.26'!$B$4:$F$4,0)),0)
B24: Adiantamento de incentivos e aplicações | C24: =IFERROR(INDEX('HOLERITE SET.26'!$B$25:$F$25,1,MATCH($C$4,'HOLERITE SET.26'!$B$4:$F$4,0)),0)
B25: Convênio | C25: =IFERROR(INDEX('HOLERITE SET.26'!$B$26:$F$26,1,MATCH($C$4,'HOLERITE SET.26'!$B$4:$F$4,0)),0)
B26: Faltas / atrasos | C26: =IFERROR(INDEX('HOLERITE SET.26'!$B$27:$F$27,1,MATCH($C$4,'HOLERITE SET.26'!$B$4:$F$4,0)),0)
B27: Vale transporte 6% | C27: =IFERROR(INDEX('HOLERITE SET.26'!$B$28:$F$28,1,MATCH($C$4,'HOLERITE SET.26'!$B$4:$F$4,0)),0)
B28: INSS | C28: =IFERROR(INDEX('HOLERITE SET.26'!$B$29:$F$29,1,MATCH($C$4,'HOLERITE SET.26'!$B$4:$F$4,0)),0)
B29: IRRF | C29: =IFERROR(INDEX('HOLERITE SET.26'!$B$30:$F$30,1,MATCH($C$4,'HOLERITE SET.26'!$B$4:$F$4,0)),0)
B30: TOTAL DE DESCONTOS | C30: =IFERROR(INDEX('HOLERITE SET.26'!$B$31:$F$31,1,MATCH($C$4,'HOLERITE SET.26'!$B$4:$F$4,0)),0)
B31: LÍQUIDO
B32: LÍQUIDO A RECEBER EM 05/10/2026 | C32: =IFERROR(INDEX('HOLERITE SET.26'!$B$33:$F$33,1,MATCH($C$4,'HOLERITE SET.26'!$B$4:$F$4,0)),0)
B34: Vendas do colaborador no mês (InovaFarma):
B35: Venda bruta | C35: =IFERROR(INDEX('BASE INOVAFARMA SET.26'!$C$5:$C$9,MATCH($C$4,'BASE INOVAFARMA SET.26'!$B$5:$B$9,0)),0)
B36: Descontos concedidos | C36: =IFERROR(INDEX('BASE INOVAFARMA SET.26'!$D$5:$D$9,MATCH($C$4,'BASE INOVAFARMA SET.26'!$B$5:$B$9,0)),0)
B37: Venda líquida | C37: =IFERROR(INDEX('BASE INOVAFARMA SET.26'!$E$5:$E$9,MATCH($C$4,'BASE INOVAFARMA SET.26'!$B$5:$B$9,0)),0)
B38: Comissão apurada | C38: =IFERROR(INDEX('BASE INOVAFARMA SET.26'!$F$5:$F$9,MATCH($C$4,'BASE INOVAFARMA SET.26'!$B$5:$B$9,0)),0)
B39: Total de incentivos | C39: =IFERROR(INDEX('BASE INOVAFARMA SET.26'!$J$5:$J$9,MATCH($C$4,'BASE INOVAFARMA SET.26'!$B$5:$B$9,0)),0)
B41: A comissão apurada acima é a do sistema. O que entra na folha é a linha "Comissão sobre vendas".
B42: Nesta loja a comissão paga é o DOBRO da apurada — por isso os dois valores são diferentes.
B43: Os valores de INSS e IRRF são calculados pela contabilidade e só aparecem depois de preenchidos na aba HOLERITE SET.26.
B44: Para mandar para o colaborador: selecione o nome acima e imprima esta aba em PDF (ou tire um print).

Sheet PONTO SET.26
A1: APONTAMENTO DO PONTO — SETEMBRO/2026
A2: Loja TRANCOSO · horas extras, adicional noturno e feriado trabalhado · alimenta a aba HOLERITE SET.26
A4: FUNCIONÁRIO | B4: OCORRÊNCIA | C4: QTDE | D4: UNIDADE | E4: SALÁRIO BASE | F4: VALOR UNITÁRIO | G4: TOTAL | H4: RUBRICA DESTINO | I4: OBSERVAÇÃO
A5: VALDICK | B5: Registro informativo | C5: 30 | D5: dias | E5: =IFERROR(INDEX('HOLERITE SET.26'!$B$6:$F$6,1,MATCH(A5,'HOLERITE SET.26'!$B$4:$F$4,0)),0) | F5: 0 | G5: =ROUND(C5*F5,2) | H5: — | I5: Férias de 01 a 30/09/2026 — mês inteiro. Salário zerado no holerite; férias e 1/3 vão em recibo próprio.
A6: TAMILES | B6: Atestado médico (abonado) | C6: 7 | D6: dias | E6: =IFERROR(INDEX('HOLERITE SET.26'!$B$6:$F$6,1,MATCH(A6,'HOLERITE SET.26'!$B$4:$F$4,0)),0) | F6: 0 | G6: =ROUND(C6*F6,2) | H6: — | I6: Atestado médico de 02 a 08/09/2026, entregue em 02/09. Até 15 dias é abonado pela empresa: falta justificada, SEM desconto de salário nem de DSR. Anexar o atestado à pasta da funcionária.
E7: =IFERROR(INDEX('HOLERITE SET.26'!$B$6:$F$6,1,MATCH(A7,'HOLERITE SET.26'!$B$4:$F$4,0)),0) | G7: =ROUND(C7*F7,2)
E8: =IFERROR(INDEX('HOLERITE SET.26'!$B$6:$F$6,1,MATCH(A8,'HOLERITE SET.26'!$B$4:$F$4,0)),0) | G8: =ROUND(C8*F8,2)
E9: =IFERROR(INDEX('HOLERITE SET.26'!$B$6:$F$6,1,MATCH(A9,'HOLERITE SET.26'!$B$4:$F$4,0)),0) | G9: =ROUND(C9*F9,2)
E10: =IFERROR(INDEX('HOLERITE SET.26'!$B$6:$F$6,1,MATCH(A10,'HOLERITE SET.26'!$B$4:$F$4,0)),0) | G10: =ROUND(C10*F10,2)
E11: =IFERROR(INDEX('HOLERITE SET.26'!$B$6:$F$6,1,MATCH(A11,'HOLERITE SET.26'!$B$4:$F$4,0)),0) | G11: =ROUND(C11*F11,2)
E12: =IFERROR(INDEX('HOLERITE SET.26'!$B$6:$F$6,1,MATCH(A12,'HOLERITE SET.26'!$B$4:$F$4,0)),0) | G12: =ROUND(C12*F12,2)
E13: =IFERROR(INDEX('HOLERITE SET.26'!$B$6:$F$6,1,MATCH(A13,'HOLERITE SET.26'!$B$4:$F$4,0)),0) | G13: =ROUND(C13*F13,2)
E14: =IFERROR(INDEX('HOLERITE SET.26'!$B$6:$F$6,1,MATCH(A14,'HOLERITE SET.26'!$B$4:$F$4,0)),0) | G14: =ROUND(C14*F14,2)
B15: TOTAL | G15: =SUM(G5:G14)
A17: Salário-hora = salário base ÷ 220. Hora extra = salário-hora × 1,5. Adicional noturno = salário-hora × 20%. Feriado trabalhado sem folga = 1 salário-dia a mais (salário base ÷ 30).
A18: No salário de R$ 1.621,00: 40 horas extras dão R$ 442,09 e 24 horas dão R$ 265,25 — é a mesma conta usada na planilha de julho.
A19: As linhas em branco são para acrescentar ocorrências: preencha funcionário, ocorrência, quantidade, valor unitário e a rubrica de destino (HORAS EXTRAS ou ADICIONAL NOTURNO).
A20: Os totais desta aba entram sozinhos nas linhas HORAS EXTRAS e ADICIONAL NOTURNO da aba HOLERITE SET.26.
