Workbook

Sheet CAPA
A1: RELATÓRIO DE FOLHA PARA A CONTABILIDADE
A4: IDENTIFICAÇÃO
B5: Empresa: Farmácia Tropical Multi Econômica
B6: Competência (mês de referência): AGOSTO/2026 — vendas de 01/08/2026 a 31/08/2026
B7: Data do pagamento: 05/09/2026
B8: Fonte das comissões e incentivos: InovaFarma — Relatório detalhado de comissão de vendedor, extraído em 03/09/2026
B9: Funcionários: DEAN, AGNOR, EDEY, JOEL, VALÉRIA, SARA, CAMILA e NATI
A10: COMO USAR ESTE ARQUIVO
B11: 1. Abra a aba HOLERITE AGO.26 — é o relatório que vai para a contabilidade.
B12: 2. Preencha as células AMARELAS (horas extras, prêmios, vales, convênio, faltas).
B13: 3. Confira as células LARANJAS — são valores repetidos de julho/2026 que podem ter mudado.
B14: 4. Comissões, incentivos e DSR já vêm calculados; não digite por cima (texto verde/preto).
B15: 5. A aba LISTA CONTABILIDADE traz os mesmos valores em formato de lista, rubrica por rubrica.
B16: 6. INSS e IRRF ficam em branco: são calculados pela contabilidade.
A17: O QUE JÁ ESTÁ APURADO (AGOSTO/2026)
B18: Comissão total apurada no InovaFarma para os 8 funcionários: R$ 4.856,68 · Incentivos: R$ 685,00
B19: Venda bruta geral do mês: R$ 300.371,95 · Descontos concedidos: R$ 90.276,65 · Venda líquida: R$ 210.095,30
B20: DSR de agosto/2026: 5 domingos (02, 09, 16, 23 e 30) ÷ 26 dias úteis = fator 0,192307
A21: APONTAMENTO DE AGOSTO/2026 (aba PONTO AGO.26)
B22: EDEY: 24 horas extras normais → R$ 265,25.
B23: NATI: 17 horas noturnas → R$ 25,05 de adicional; e o feriado de 15/08 trabalhado sem folga → R$ 54,03.
B24: CAMILA, SARA e VALÉRIA: dia 15/08 (feriado) trabalhado → R$ 54,03 cada.
B25: VALÉRIA: 2 madrugadas com folga no dia seguinte — cabe só o adicional noturno; falta informar as horas.
B26: AGNOR: 3 madrugadas com folga — cabe só o adicional noturno; falta informar as horas.
B27: DEAN: dia 15/08 trabalhado com folga compensatória — nada a pagar.
A28: JÁ DEFINIDO PELA EMPRESA
B29: AGNOR: mantida a comissão fixa de R$ 2.000,00 — a linha COMPLEMENTO / COMISSÃO PDV calcula sozinha a diferença (R$ 1.090,49) sobre o apurado de R$ 909,51.
B30: JOEL: por acordo interno saiu em 04/08 e volta em 04/09, mas o recibo de férias saiu como 01 a 31/08 e já foi pago no início de agosto. Por isso ele tem comissão dos dias 01 e 02/08 (R$ 103,31) e fica sem salário e sem desconto de vale-transporte neste holerite; férias e 1/3 NÃO se repetem aqui.
B31: CAMILA: contratada recentemente; agosto é o primeiro mês completo, com salário integral de R$ 1.621,00.
B32: SARA: a comissão dela na loja Centro (R$ 2,65) foi somada aqui, na linha COMPLEMENTO / COMISSÃO PDV.
B33: DEAN: não recebe comissão sobre vendas — a rubrica fica zerada na folha (a apurada, R$ 975,65, aparece só na aba BASE). Os incentivos dele continuam sendo pagos normalmente.
A34: PENDÊNCIAS — CONFIRMAR ANTES DE ENVIAR
A35: • | B35: VALÉRIA e AGNOR: informar na aba PONTO AGO.26 quantas horas noturnas tiveram as madrugadas trabalhadas (2 e 3 madrugadas).
A36: • | B36: EDEY: o adicional noturno está lançado como valor fixo de R$ 350,00 — conferir com o apontamento do ponto.
A37: • | B37: Confirmar o critério do feriado trabalhado: está sendo pago 1 salário-dia a mais (R$ 54,03) por feriado sem folga.
A38: • | B38: Prêmio cota geral e prêmio pré-vencidos de agosto.
A39: • | B39: Vales adiantados, convênio e faltas de agosto.
A40: • | B40: JOEL: confirmar se há algum desconto para agosto (convênio, vale ou adiantamento) — hoje o holerite dele fica só com a comissão de R$ 103,31 e o DSR.
A41: • | B41: JOEL: como o retorno é em 04/09, o vale-transporte de setembro deve ser proporcional e o holerite de setembro ainda pega os dias 01 a 03/09 de férias, já pagos no recibo de agosto.
A42: • | B42: Comissões de PDV antigos, que em julho eram somadas à comissão do sistema.
...

Sheet PARÂMETROS
A1: PARÂMETROS DE CÁLCULO
A2: Farmácia Tropical Multi Econômica — competência AGOSTO/2026
A4: COMPETÊNCIA / PAGAMENTO
A5: Competência (mês de referência) | B5: AGOSTO/2026 | C5: Vendas de 01/08/2026 a 31/08/2026 (relatório InovaFarma).
A6: Data do pagamento | B6: 05/09/2026 | C6: Folha a ser lançada no holerite pago em 05/09/2026.
A7: Data de extração do InovaFarma | B7: 03/09/2026 | C7: Arquivo Comissao_de_Vendedores03092026_080157.xlsx.
A8: CALENDÁRIO DO MÊS (base do DSR)
A9: Dias do mês | B9: 31 | C9: Agosto/2026.
A10: Domingos + feriados | B10: 5 | C10: Domingos: 02, 09, 16, 23 e 30/08/2026. Sem feriado nacional em agosto.
A11: Dias úteis (inclui sábados) | B11: =B9-B10 | C11: Dias do mês menos domingos e feriados.
A12: Fator DSR (domingos ÷ dias úteis) | B12: =B10/B11 | C12: Domingos ÷ dias úteis. Usado na rubrica REPOUSO REMUNERADO / DSR da aba HOLERITE AGO.26.
A13: VALORES FIXOS / RECORRENTES
A14: Salário base (piso 2026) | B14: 1621 | C14: Valor praticado em jul/2026 para todos, exceto DEAN.
A15: Salário DEAN | B15: 5648.41 | C15: Conforme jul/2026.
A16: Auxílio gerência | B16: 810.5 | C16: AGNOR e SARA (conforme jul/2026).
A17: Adicional prêmio meta caixa | B17: 307.99 | C17: VALÉRIA e NATI (conforme jul/2026).
A18: Adicional noturno EDEY | B18: 350 | C18: Conforme jul/2026 — conferir apontamento do ponto.
A19: Comissão fixa acordada — AGNOR | B19: 2000 | C19: Valor fixo mantido pela empresa. O complemento é a diferença entre este valor e a comissão apurada no InovaFarma.
A20: Horas mensais (base do salário-hora) | B20: 220 | C20: Salário-hora = salário base ÷ 220.
A21: Adicional de hora extra | B21: 0.5 | C21: 50% sobre a hora normal (hora extra = salário-hora × 1,5).
A22: Adicional noturno | B22: 0.2 | C22: 20% sobre a hora normal, nas horas entre 22h e 5h.
A23: Dias do mês para o salário-dia | B23: 30 | C23: Salário-dia = salário base ÷ 30. Usado no feriado trabalhado.
A24: Desconto vale-transporte 6% | B24: -84.29 | C24: Valor praticado em jul/2026. 6% do salário base daria R$ 97,26 — CONFERIR.
A25: INSS / IRRF
A26: INSS | B26: a calcular | C26: Calculado pela contabilidade sobre o total de proventos (tabela progressiva vigente).
A27: IRRF | B27: a calcular | C27: Calculado pela contabilidade após dedução do INSS e dependentes.

Sheet BASE INOVAFARMA AGO.26
A1: APURAÇÃO DE COMISSÕES E INCENTIVOS — INOVAFARMA
A2: Relatório detalhado de comissão de vendedor · vendas de 01/08/2026 a 31/08/2026 · extraído em 03/09/2026
A4: CÓD. | B4: VENDEDOR | C4: VENDA BRUTA | D4: DESCONTOS | E4: VENDA LÍQUIDA | F4: COMISSÃO | G4: INCENT. APLIC. | H4: INCENT. VITAM. | I4: OUTROS INCENT. | J4: TOTAL INCENT.
A5: 242 | B5: DEAN | C5: 53167.33 | D5: 22509.36 | E5: 30657.97 | F5: 975.65 | G5: 190 | H5: 0 | I5: 9 | J5: =SUM(G5:I5)
A6: 53 | B6: AGNOR | C6: 51871.06 | D6: 19353.31 | E6: 32517.75 | F6: 909.51 | G6: 150 | H6: 25 | I6: 14 | J6: =SUM(G6:I6)
A7: 272 | B7: EDEY | C7: 49696.15 | D7: 18497.95 | E7: 31198.2 | F7: 873.76 | G7: 40 | H7: 30 | I7: 3 | J7: =SUM(G7:I7)
A8: 181 | B8: JOEL | C8: 5057.69 | D8: 1361.04 | E8: 3696.65 | F8: 103.31 | G8: 20 | H8: 0 | I8: 2 | J8: =SUM(G8:I8)
A9: 292 | B9: VALÉRIA | C9: 61902.54 | D9: 22544.73 | E9: 39357.81 | F9: 1141.03 | G9: 140 | H9: 35 | I9: 17 | J9: =SUM(G9:I9)
A10: 43 | B10: SARA | C10: 29798.09 | D10: 3068.04 | E10: 26730.05 | F10: 368.78 | G10: 0 | H10: 0 | I10: 10 | J10: =SUM(G10:I10)
A11: 312 | B11: CAMILA | C11: 21520.43 | D11: 1007.45 | E11: 20512.98 | F11: 241.5 | G11: 0 | H11: 0 | I11: 0 | J11: =SUM(G11:I11)
A12: 212 | B12: NATI | C12: 26696.39 | D12: 1321.75 | E12: 25374.64 | F12: 243.14 | G12: 0 | H12: 0 | I12: 0 | J12: =SUM(G12:I12)
B13: TOTAL FUNCIONÁRIOS | C13: =SUM(C5:C12) | D13: =SUM(D5:D12) | E13: =SUM(E5:E12) | F13: =SUM(F5:F12) | G13: =SUM(G5:G12) | H13: =SUM(H5:H12) | I13: =SUM(I5:I12) | J13: =SUM(J5:J12)
A15: Códigos sem vínculo de folha (não entram no holerite):
A16: 11 | B16: GILSON MOURA SANTOS | C16: 603.28 | F16: 0.0018
A17: 41 | B17: PEDRO | C17: 10.41 | F17: 0
A18: 73 | B18: BALCONISTA | C18: 48.58 | F18: 0
A20: CONFERÊNCIA — total geral do relatório InovaFarma: venda bruta R$ 300.371,95 · descontos R$ 90.276,65 · venda líquida R$ 210.095,30 · comissão R$ 4.856,69 · incentivo R$ 685,00.
A21: INCENT. APLIC. = incentivo do grupo INJETÁVEIS (aplicações). INCENT. VITAM. = grupo APLICAÇÃO E VITAMINAS INCENTIVO. OUTROS INCENT. = populares, oficinais e similar normal.
A22: A comissão acima é a APURADA pelo sistema. Comissões de PDV antigos e valores fixos acordados são lançados à parte na aba HOLERITE AGO.26.
A23: SARA também vendeu R$ 365,03 pelo código dela na loja CENTRO, com R$ 2,65 de comissão. Esse valor foi somado à folha dela aqui, na linha COMPLEMENTO / COMISSÃO PDV.
A24: DEAN não recebe comissão em folha: no caso dele a comissão apurada acima é apenas informativa. Os incentivos dele continuam sendo lançados normalmente.
A25: JOEL: vendeu R$ 3.684,97 nos dias 01 e 02/08 e saiu de férias em 04/08 (retorno em 04/09) — daí a comissão de R$ 103,31. Constam ainda 2 itens de R$ 11,68 em 07/08 no código dele.

Sheet HOLERITE AGO.26
A1: RELATÓRIO PARA A CONTABILIDADE — LANÇAMENTO EM HOLERITE
A2: Competência AGOSTO/2026 (01/08 a 31/08/2026) · Pagamento em 05/09/2026 · Farmácia Tropical Multi Econômica
A4: RUBRICA | B4: DEAN | C4: AGNOR | D4: EDEY | E4: JOEL | F4: VALÉRIA | G4: SARA | H4: CAMILA | I4: NATI | J4: TOTAL | K4: ORIGEM / OBSERVAÇÃO
A5: PROVENTOS
A6: SALÁRIO BASE | B6: 5648.41 | C6: 1621 | D6: 1621 | E6: 0 | F6: 1621 | G6: 1621 | H6: 1621 | I6: 1621 | J6: =SUM(B6:I6) | K6: Piso 2026 R$ 1.621,00. CAMILA: admitida em jul/26 (salário proporcional naquele mês); agosto é o 1º mês completo. JOEL: zerado — trabalhou de 01 a 03/08 mas esses dias já estão dentro do recibo de férias (01 a 31/08); se a empresa decidir pagá-los à parte, lançar aqui.
A7: ADICIONAL NOTURNO | B7: =SUMIFS('PONTO AGO.26'!$G$5:$G$20,'PONTO AGO.26'!$A$5:$A$20,B$4,'PONTO AGO.26'!$H$5:$H$20,"ADICIONAL NOTURNO") | C7: =SUMIFS('PONTO AGO.26'!$G$5:$G$20,'PONTO AGO.26'!$A$5:$A$20,C$4,'PONTO AGO.26'!$H$5:$H$20,"ADICIONAL NOTURNO") | D7: =SUMIFS('PONTO AGO.26'!$G$5:$G$20,'PONTO AGO.26'!$A$5:$A$20,D$4,'PONTO AGO.26'!$H$5:$H$20,"ADICIONAL NOTURNO") | E7: =SUMIFS('PONTO AGO.26'!$G$5:$G$20,'PONTO AGO.26'!$A$5:$A$20,E$4,'PONTO AGO.26'!$H$5:$H$20,"ADICIONAL NOTURNO") | F7: =SUMIFS('PONTO AGO.26'!$G$5:$G$20,'PONTO AGO.26'!$A$5:$A$20,F$4,'PONTO AGO.26'!$H$5:$H$20,"ADICIONAL NOTURNO") | G7: =SUMIFS('PONTO AGO.26'!$G$5:$G$20,'PONTO AGO.26'!$A$5:$A$20,G$4,'PONTO AGO.26'!$H$5:$H$20,"ADICIONAL NOTURNO") | H7: =SUMIFS('PONTO AGO.26'!$G$5:$G$20,'PONTO AGO.26'!$A$5:$A$20,H$4,'PONTO AGO.26'!$H$5:$H$20,"ADICIONAL NOTURNO") | I7: =SUMIFS('PONTO AGO.26'!$G$5:$G$20,'PONTO AGO.26'!$A$5:$A$20,I$4,'PONTO AGO.26'!$H$5:$H$20,"ADICIONAL NOTURNO") | J7: =SUM(B7:I7) | K7: Somado automaticamente da aba PONTO AGO.26 (apontamento de agosto/2026). Para mudar, edite lá.
A8: HORAS EXTRAS | B8: =SUMIFS('PONTO AGO.26'!$G$5:$G$20,'PONTO AGO.26'!$A$5:$A$20,B$4,'PONTO AGO.26'!$H$5:$H$20,"HORAS EXTRAS") | C8: =SUMIFS('PONTO AGO.26'!$G$5:$G$20,'PONTO AGO.26'!$A$5:$A$20,C$4,'PONTO AGO.26'!$H$5:$H$20,"HORAS EXTRAS") | D8: =SUMIFS('PONTO AGO.26'!$G$5:$G$20,'PONTO AGO.26'!$A$5:$A$20,D$4,'PONTO AGO.26'!$H$5:$H$20,"HORAS EXTRAS") | E8: =SUMIFS('PONTO AGO.26'!$G$5:$G$20,'PONTO AGO.26'!$A$5:$A$20,E$4,'PONTO AGO.26'!$H$5:$H$20,"HORAS EXTRAS") | F8: =SUMIFS('PONTO AGO.26'!$G$5:$G$20,'PONTO AGO.26'!$A$5:$A$20,F$4,'PONTO AGO.26'!$H$5:$H$20,"HORAS EXTRAS") | G8: =SUMIFS('PONTO AGO.26'!$G$5:$G$20,'PONTO AGO.26'!$A$5:$A$20,G$4,'PONTO AGO.26'!$H$5:$H$20,"HORAS EXTRAS") | H8: =SUMIFS('PONTO AGO.26'!$G$5:$G$20,'PONTO AGO.26'!$A$5:$A$20,H$4,'PONTO AGO.26'!$H$5:$H$20,"HORAS EXTRAS") | I8: =SUMIFS('PONTO AGO.26'!$G$5:$G$20,'PONTO AGO.26'!$A$5:$A$20,I$4,'PONTO AGO.26'!$H$5:$H$20,"HORAS EXTRAS") | J8: =SUM(B8:I8) | K8: Somado automaticamente da aba PONTO AGO.26 (apontamento de agosto/2026). Para mudar, edite lá.
A9: COMISSÃO PRODUTOS (INOVAFARMA) | B9: 0 | C9: ='BASE INOVAFARMA AGO.26'!F6 | D9: ='BASE INOVAFARMA AGO.26'!F7 | E9: ='BASE INOVAFARMA AGO.26'!F8 | F9: ='BASE INOVAFARMA AGO.26'!F9 | G9: ='BASE INOVAFARMA AGO.26'!F10 | H9: ='BASE INOVAFARMA AGO.26'!F11 | I9: ='BASE INOVAFARMA AGO.26'!F12 | J9: =SUM(B9:I9) | K9: Apurado no InovaFarma (aba BASE INOVAFARMA AGO.26). JOEL: R$ 103,31 das vendas dele nos dias 01 e 02/08, antes de sair de férias em 04/08 (o recibo de férias saiu como 01 a 31/08). DEAN NÃO RECEBE COMISSÃO — lançado zero (o apurado dele fica só como informação na aba BASE). AGNOR: mantido o fixo de R$ 2.000,00 pela linha de complemento abaixo.
A10: COMPLEMENTO / COMISSÃO PDV | C10: =ROUND(PARÂMETROS!$B$19-C9,2) | G10: 2.65 | J10: =SUM(B10:I10) | K10: AGNOR: complemento até a comissão fixa de R$ 2.000,00 (parâmetro na aba PARÂMETROS). SARA: R$ 2,65 de comissão apurada no código dela na loja CENTRO (venda bruta de R$ 365,03), trazida para a folha do Arraial. Demais: preencher com PDV antigos, se houver.
A11: =COMISSÃO TOTAL | B11: =SUM(B9:B10) | C11: =SUM(C9:C10) | D11: =SUM(D9:D10) | E11: =SUM(E9:E10) | F11: =SUM(F9:F10) | G11: =SUM(G9:G10) | H11: =SUM(H9:H10) | I11: =SUM(I9:I10) | J11: =SUM(B11:I11) | K11: Base do DSR junto com as horas extras.
A12: REPOUSO REMUNERADO / DSR | B12: =ROUND((B11+B8)*PARÂMETROS!$B$12,2) | C12: =ROUND((C11+C8)*PARÂMETROS!$B$12,2) | D12: =ROUND((D11+D8)*PARÂMETROS!$B$12,2) | E12: =ROUND((E11+E8)*PARÂMETROS!$B$12,2) | F12: =ROUND((F11+F8)*PARÂMETROS!$B$12,2) | G12: =ROUND((G11+G8)*PARÂMETROS!$B$12,2) | H12: =ROUND((H11+H8)*PARÂMETROS!$B$12,2) | I12: =ROUND((I11+I8)*PARÂMETROS!$B$12,2) | J12: =SUM(B12:I12) | K12: =(comissão total + horas extras) × 5 domingos ÷ 26 dias úteis de agosto/2026 (fator na aba PARÂMETROS).
A13: AUXÍLIO GERÊNCIA | C13: 810.5 | G13: 810.5 | J13: =SUM(B13:I13) | K13: AGNOR e SARA — valor recorrente de jul/26.
A14: ADICIONAL PRÊMIO META CAIXA | F14: 307.99 | I14: 307.99 | J14: =SUM(B14:I14) | K14: VALÉRIA e NATI — valor recorrente de jul/26; confirmar se a meta foi batida em agosto.
A15: PRÊMIO COTA GERAL | J15: =SUM(B15:I15) | K15: PREENCHER conforme apuração de metas de agosto.
A16: PRÊMIO PRÉ-VENCIDOS | J16: =SUM(B16:I16) | K16: PREENCHER conforme apuração de pré-vencidos de agosto.
A17: FÉRIAS (DIAS GOZADOS) | J17: =SUM(B17:I17) | K17: JOEL: recibo de férias de 01 a 31/08/2026, JÁ PAGO no início de agosto — NÃO lançar de novo aqui. Pelo acordo interno ele saiu em 04/08 e volta em 04/09.
A18: 1/3 CONSTITUCIONAL DE FÉRIAS | J18: =SUM(B18:I18) | K18: JOEL: também já pago com as férias no início de agosto. Linha mantida para eventuais férias de outros meses.
A19: INCENTIVO APLICAÇÕES | B19: ='BASE INOVAFARMA AGO.26'!G5 | C19: ='BASE INOVAFARMA AGO.26'!G6 | D19: ='BASE INOVAFARMA AGO.26'!G7 | E19: ='BASE INOVAFARMA AGO.26'!G8 | F19: ='BASE INOVAFARMA AGO.26'!G9 | G19: ='BASE INOVAFARMA AGO.26'!G10 | H19: ='BASE INOVAFARMA AGO.26'!G11 | I19: ='BASE INOVAFARMA AGO.26'!G12 | J19: =SUM(B19:I19) | K19: Incentivo de injetáveis apurado no InovaFarma.
A20: INCENTIVO VITAMINAS | B20: ='BASE INOVAFARMA AGO.26'!H5 | C20: ='BASE INOVAFARMA AGO.26'!H6 | D20: ='BASE INOVAFARMA AGO.26'!H7 | E20: ='BASE INOVAFARMA AGO.26'!H8 | F20: ='BASE INOVAFARMA AGO.26'!H9 | G20: ='BASE INOVAFARMA AGO.26'!H10 | H20: ='BASE INOVAFARMA AGO.26'!H11 | I20: ='BASE INOVAFARMA AGO.26'!H12 | J20: =SUM(B20:I20) | K20: Grupo APLICAÇÃO E VITAMINAS INCENTIVO no InovaFarma.
A21: OUTROS INCENTIVOS | B21: ='BASE INOVAFARMA AGO.26'!I5 | C21: ='BASE INOVAFARMA AGO.26'!I6 | D21: ='BASE INOVAFARMA AGO.26'!I7 | E21: ='BASE INOVAFARMA AGO.26'!I8 | F21: ='BASE INOVAFARMA AGO.26'!I9 | G21: ='BASE INOVAFARMA AGO.26'!I10 | H21: ='BASE INOVAFARMA AGO.26'!I11 | I21: ='BASE INOVAFARMA AGO.26'!I12 | J21: =SUM(B21:I21) | K21: Populares, oficinais e similar normal.
A22: TOTAL DE PROVENTOS | B22: =SUM(B6:B21)-B9-B10 | C22: =SUM(C6:C21)-C9-C10 | D22: =SUM(D6:D21)-D9-D10 | E22: =SUM(E6:E21)-E9-E10 | F22: =SUM(F6:F21)-F9-F10 | G22: =SUM(G6:G21)-G9-G10 | H22: =SUM(H6:H21)-H9-H10 | I22: =SUM(I6:I21)-I9-I10 | J22: =SUM(B22:I22) | K22: Soma das rubricas acima (a linha COMISSÃO TOTAL já engloba comissão InovaFarma + complemento PDV).
A23: DESCONTOS (lançar com sinal negativo)
A24: ADIANTAMENTO / VALES | J24: =SUM(B24:I24) | K24: PREENCHER com os vales adiantados durante agosto.
A25: ADIANT. VALES INCENT. E APLIC. | B25: =-(B19+B20+B21) | C25: =-(C19+C20+C21) | D25: =-(D19+D20+D21) | E25: =-(E19+E20+E21) | F25: =-(F19+F20+F21) | G25: =-(G19+G20+G21) | H25: =-(H19+H20+H21) | I25: =-(I19+I20+I21) | J25: =SUM(B25:I25) | K25: Estorno dos incentivos já adiantados em dinheiro no mês (mesmo critério de jul/26). AJUSTAR se algum incentivo não foi adiantado.
A26: CONVÊNIO | J26: =SUM(B26:I26) | K26: PREENCHER (jul/26: AGNOR -300, JOEL -500, VALÉRIA -300, SARA -300).
A27: DESCONTO FALTAS / ATRASOS | J27: =SUM(B27:I27) | K27: PREENCHER conforme o ponto.
A28: DESCONTO VALE TRANSPORTE 6% | D28: -84.29 | F28: -84.29 | I28: -84.29 | J28: =SUM(B28:I28) | K28: Valor praticado em jul/26. 6% sobre R$ 1.621,00 seria R$ 97,26 — CONFERIR a base usada. JOEL: zerado, mês de férias.
A29: DESCONTO INSS | J29: =SUM(B29:I29) | K29: A CALCULAR PELA CONTABILIDADE sobre o total de proventos (tabela progressiva vigente).
A30: DESCONTO IRRF | J30: =SUM(B30:I30) | K30: A CALCULAR PELA CONTABILIDADE.
A31: TOTAL DE DESCONTOS | B31: =SUM(B24:B30) | C31: =SUM(C24:C30) | D31: =SUM(D24:D30) | E31: =SUM(E24:E30) | F31: =SUM(F24:F30) | G31: =SUM(G24:G30) | H31: =SUM(H24:H30) | I31: =SUM(I24:I30) | J31: =SUM(B31:I31)
A32: LÍQUIDO
A33: LÍQUIDO A RECEBER (05/09/2026) | B33: =B22+B31 | C33: =C22+C31 | D33: =D22+D31 | E33: =E22+E31 | F33: =F22+F31 | G33: =G22+G31 | H33: =H22+H31 | I33: =I22+I31 | J33: =SUM(B33:I33) | K33: Total de proventos menos descontos. Só fica definitivo depois do INSS/IRRF da contabilidade.
A34: INFORMATIVO — PAGO PELA EMPRESA, NÃO ENTRA NO HOLERITE
A35: VALE TRANSPORTE (compra set/26) | J35: =SUM(B35:I35) | K35: PREENCHER com as passagens compradas para setembro/2026. JOEL: só a partir de 04/09, quando volta das férias.
A36: VALE ALIMENTAÇÃO FERIADOS E DOMINGOS | J36: =SUM(B36:I36) | K36: PREENCHER conforme escala de domingos/feriados de agosto.
A38: LEGENDA
A39: Célula amarela, texto azul | B39: valor digitado — PREENCHER ou conferir antes de enviar.
A40: Célula laranja | B40: valor repetido de julho/2026 — CONFERIR se continua válido em agosto.
A41: Texto verde | B41: valor puxado da aba BASE INOVAFARMA AGO.26 (não digitar por cima).
A42: Texto preto em célula verde | B42: resultado de fórmula — não alterar.

Sheet JULHO.26 REVISADO
A1: FOLHA REVISADA — COMPETÊNCIA JULHO/2026 (paga em 05/08/2026)
A2: Mesmos valores efetivamente pagos, reorganizados e com fórmulas conferidas · confronto com o cálculo correto do DSR
A4: RUBRICA | B4: DEAN | C4: AGNOR | D4: EDEY | E4: JOEL | F4: VALÉRIA | G4: SARA | H4: CAMILA | I4: NATI | J4: TOTAL | K4: ORIGEM / OBSERVAÇÃO
A5: PROVENTOS
A6: SALÁRIO BASE | B6: 5648.41 | C6: 1621 | D6: 1621 | E6: 1621 | F6: 1621 | G6: 1621 | H6: 595 | I6: 1621 | J6: =SUM(B6:I6) | K6: CAMILA proporcional (admissão no mês).
A7: ADICIONAL NOTURNO | D7: 350 | J7: =SUM(B7:I7)
A8: HORAS EXTRAS | D8: 442.09 | I8: 221.05 | J8: =SUM(B8:I8) | K8: Valor lançado na folha. O DSR foi calculado sobre o dobro deste valor — verificar qual é o valor correto das horas extras.
A9: COMISSÃO PRODUTOS + PDV | C9: 2000 | D9: 1202 | E9: 1693.68 | F9: 1071 | G9: 345 | H9: 120 | I9: 280 | J9: =SUM(B9:I9) | K9: Comissão do InovaFarma somada aos PDV antigos.
A10: REPOUSO REMUNERADO / DSR | C10: 384.62 | D10: 401.19 | E10: 325.71 | F10: 205.96 | G10: 66.35 | I10: 138.87 | J10: =SUM(B10:I10) | K10: Pago com fator 5/26 = 0,192307 (calendário de AGOSTO). Julho/2026 tem 4 domingos e 27 dias úteis → fator correto 0,148148. Ver conferência abaixo.
A11: AUXÍLIO GERÊNCIA | C11: 810.5 | G11: 810.5 | J11: =SUM(B11:I11)
A12: ADICIONAL PRÊMIO META CAIXA | F12: 307.99 | I12: 307.99 | J12: =SUM(B12:I12)
A13: PRÊMIO COTA GERAL | D13: 250 | E13: 250 | F13: 250 | G13: 150 | I13: 150 | J13: =SUM(B13:I13)
A14: PRÊMIO PRÉ-VENCIDOS | D14: 100 | E14: 200 | F14: 250 | G14: 100 | I14: 100 | J14: =SUM(B14:I14)
A15: INCENTIVO APLICAÇÕES | C15: 264 | D15: 100 | E15: 290 | F15: 292 | J15: =SUM(B15:I15)
A16: INCENTIVO VITAMINAS | F16: 40 | J16: =SUM(B16:I16)
A17: TOTAL DE PROVENTOS | B17: =SUM(B6:B16) | C17: =SUM(C6:C16) | D17: =SUM(D6:D16) | E17: =SUM(E6:E16) | F17: =SUM(F6:F16) | G17: =SUM(G6:G16) | H17: =SUM(H6:H16) | I17: =SUM(I6:I16) | J17: =SUM(B17:I17)
A18: DESCONTOS
A19: ADIANTAMENTO / VALES | C19: -2300 | D19: -1500 | E19: -1300 | F19: -1300 | G19: -1200 | J19: =SUM(B19:I19)
A20: ADIANT. VALES INCENT. E APLIC. | C20: -264 | D20: -100 | E20: -290 | F20: -332 | J20: =SUM(B20:I20)
A21: CONVÊNIO | C21: -300 | E21: -500 | F21: -300 | G21: -300 | J21: =SUM(B21:I21)
A22: DESCONTO FALTAS | J22: =SUM(B22:I22)
A23: DESCONTO VALE TRANSPORTE 6% | D23: -84.29 | E23: -84.29 | F23: -84.29 | I23: -84.29 | J23: =SUM(B23:I23)
A24: DESCONTO INSS | B24: -592.27 | C24: -480.85 | D24: -426.78 | E24: -414.75 | F24: -373.14 | G24: -213.94 | I24: -229.38 | J24: =SUM(B24:I24)
A25: DESCONTO IRRF | B25: -251.04 | J25: =SUM(B25:I25)
A26: TOTAL DE DESCONTOS | B26: =SUM(B19:B25) | C26: =SUM(C19:C25) | D26: =SUM(D19:D25) | E26: =SUM(E19:E25) | F26: =SUM(F19:F25) | G26: =SUM(G19:G25) | H26: =SUM(H19:H25) | I26: =SUM(I19:I25) | J26: =SUM(B26:I26)
A27: LÍQUIDO
A28: LÍQUIDO PAGO (05/08/2026) | B28: =B17+B26 | C28: =C17+C26 | D28: =D17+D26 | E28: =E17+E26 | F28: =F17+F26 | G28: =G17+G26 | H28: =H17+H26 | I28: =I17+I26 | J28: =SUM(B28:I28)
A29: SALDO FINAL DA PLANILHA ORIGINAL | B29: 4805.1 | C29: 1735.27 | D29: 2355.21 | E29: 1791.35 | F29: 1648.52 | G29: 1378.91 | H29: 715 | I29: 2505.24 | J29: =SUM(B29:I29) | K29: Valor que constava na aba AGOSTOJULHO.26 do arquivo original.
A30: DIFERENÇA (revisado − original) | B30: =ROUND(B28-B29,2) | C30: =ROUND(C28-C29,2) | D30: =ROUND(D28-D29,2) | E30: =ROUND(E28-E29,2) | F30: =ROUND(F28-F29,2) | G30: =ROUND(G28-G29,2) | H30: =ROUND(H28-H29,2) | I30: =ROUND(I28-I29,2) | J30: =SUM(B30:I30) | K30: Deve ser zero — confirma que a revisão não alterou nenhum valor pago.
A31: CONFERÊNCIA DO DSR DE JULHO/2026 (não altera o que já foi pago — decidir se ajusta em setembro)
A32: DSR pago (fator 5/26) | B32: =B10 | C32: =C10 | D32: =D10 | E32: =E10 | F32: =F10 | G32: =G10 | H32: =H10 | I32: =I10 | J32: =SUM(B32:I32) | K32: Fator do calendário de agosto aplicado por engano na competência de julho.
A33: DSR recalculado (fator 4/27 · comissão + HE) | B33: =ROUND((B9+B8)*4/27,2) | C33: =ROUND((C9+C8)*4/27,2) | D33: =ROUND((D9+D8)*4/27,2) | E33: =ROUND((E9+E8)*4/27,2) | F33: =ROUND((F9+F8)*4/27,2) | G33: =ROUND((G9+G8)*4/27,2) | H33: =ROUND((H9+H8)*4/27,2) | I33: =ROUND((I9+I8)*4/27,2) | J33: =SUM(B33:I33) | K33: Julho/2026: 4 domingos (05, 12, 19 e 26) e 27 dias úteis.
A34: Diferença de DSR (a menor/maior) | B34: =ROUND(B33-B32,2) | C34: =ROUND(C33-C32,2) | D34: =ROUND(D33-D32,2) | E34: =ROUND(E33-E32,2) | F34: =ROUND(F33-F32,2) | G34: =ROUND(G33-G32,2) | H34: =ROUND(H33-H32,2) | I34: =ROUND(I33-I32,2) | J34: =SUM(B34:I34) | K34: Valor negativo = foi pago a mais em julho. Decidir com a contabilidade se compensa em set/26.
A35: INFORMATIVO — PAGO PELA EMPRESA, NÃO ENTRA NO HOLERITE
A36: VALE TRANSPORTE (passagens de agosto) | B36: 350 | D36: 416 | F36: 500 | H36: 135 | I36: 288 | J36: =SUM(B36:I36) | K36: Compra registrada na planilha original.
A37: VALE ALIMENTAÇÃO FERIADOS E DOMINGOS | B37: 647 | C37: 84 | D37: 48 | E37: 50 | F37: 75 | G37: 84 | J37: =SUM(B37:I37)
A39: AJUSTES FEITOS NESTA REVISÃO (a planilha original continua intacta no arquivo enviado):
A40: 1. Fórmulas de SALDO FINAL corrigidas — na original o total do DEAN pulava a linha 17 e o do AGNOR começava na linha 4, deixando linhas de fora da soma.
A41: 2. Rubricas separadas em PROVENTOS × DESCONTOS, com subtotais próprios, em vez de uma soma única.
A42: 3. Nomes de rubrica padronizados e coluna de observação com a origem de cada valor.
...

Sheet LISTA CONTABILIDADE
A1: LANÇAMENTOS POR FUNCIONÁRIO — AGOSTO/2026 (pagamento 05/09/2026)
A2: Mesmos valores da aba HOLERITE AGO.26, em formato de lista (os valores são vinculados por fórmula)
A4: FUNCIONÁRIO | B4: RUBRICA | C4: TIPO | D4: VALOR | E4: OBSERVAÇÃO
A5: DEAN | B5: SALÁRIO BASE | C5: Provento | D5: ='HOLERITE AGO.26'!B6
A6: DEAN | B6: ADICIONAL NOTURNO | C6: Provento | D6: ='HOLERITE AGO.26'!B7
A7: DEAN | B7: HORAS EXTRAS | C7: Provento | D7: ='HOLERITE AGO.26'!B8
A8: DEAN | B8: COMISSÃO SOBRE VENDAS | C8: Provento | D8: ='HOLERITE AGO.26'!B11
A9: DEAN | B9: REPOUSO REMUNERADO / DSR | C9: Provento | D9: ='HOLERITE AGO.26'!B12
A10: DEAN | B10: AUXÍLIO GERÊNCIA | C10: Provento | D10: ='HOLERITE AGO.26'!B13
A11: DEAN | B11: ADICIONAL PRÊMIO META CAIXA | C11: Provento | D11: ='HOLERITE AGO.26'!B14
A12: DEAN | B12: PRÊMIO COTA GERAL | C12: Provento | D12: ='HOLERITE AGO.26'!B15
A13: DEAN | B13: PRÊMIO PRÉ-VENCIDOS | C13: Provento | D13: ='HOLERITE AGO.26'!B16
A14: DEAN | B14: INCENTIVO APLICAÇÕES | C14: Provento | D14: ='HOLERITE AGO.26'!B19
A15: DEAN | B15: INCENTIVO VITAMINAS | C15: Provento | D15: ='HOLERITE AGO.26'!B20
A16: DEAN | B16: OUTROS INCENTIVOS | C16: Provento | D16: ='HOLERITE AGO.26'!B21
A17: DEAN | B17: TOTAL DE PROVENTOS | C17: Subtotal | D17: ='HOLERITE AGO.26'!B22
A18: DEAN | B18: ADIANTAMENTO / VALES | C18: Desconto | D18: ='HOLERITE AGO.26'!B24
A19: DEAN | B19: ADIANT. VALES INCENT. E APLIC. | C19: Desconto | D19: ='HOLERITE AGO.26'!B25
A20: DEAN | B20: CONVÊNIO | C20: Desconto | D20: ='HOLERITE AGO.26'!B26
A21: DEAN | B21: DESCONTO FALTAS / ATRASOS | C21: Desconto | D21: ='HOLERITE AGO.26'!B27
A22: DEAN | B22: DESCONTO VALE TRANSPORTE 6% | C22: Desconto | D22: ='HOLERITE AGO.26'!B28
A23: DEAN | B23: DESCONTO INSS | C23: Desconto | D23: ='HOLERITE AGO.26'!B29
A24: DEAN | B24: DESCONTO IRRF | C24: Desconto | D24: ='HOLERITE AGO.26'!B30
A25: DEAN | B25: TOTAL DE DESCONTOS | C25: Subtotal | D25: ='HOLERITE AGO.26'!B31
A26: DEAN | B26: LÍQUIDO A RECEBER | C26: Líquido | D26: ='HOLERITE AGO.26'!B33
A28: AGNOR | B28: SALÁRIO BASE | C28: Provento | D28: ='HOLERITE AGO.26'!C6
A29: AGNOR | B29: ADICIONAL NOTURNO | C29: Provento | D29: ='HOLERITE AGO.26'!C7
A30: AGNOR | B30: HORAS EXTRAS | C30: Provento | D30: ='HOLERITE AGO.26'!C8
A31: AGNOR | B31: COMISSÃO SOBRE VENDAS | C31: Provento | D31: ='HOLERITE AGO.26'!C11
A32: AGNOR | B32: REPOUSO REMUNERADO / DSR | C32: Provento | D32: ='HOLERITE AGO.26'!C12
A33: AGNOR | B33: AUXÍLIO GERÊNCIA | C33: Provento | D33: ='HOLERITE AGO.26'!C13
A34: AGNOR | B34: ADICIONAL PRÊMIO META CAIXA | C34: Provento | D34: ='HOLERITE AGO.26'!C14
A35: AGNOR | B35: PRÊMIO COTA GERAL | C35: Provento | D35: ='HOLERITE AGO.26'!C15
A36: AGNOR | B36: PRÊMIO PRÉ-VENCIDOS | C36: Provento | D36: ='HOLERITE AGO.26'!C16
A37: AGNOR | B37: INCENTIVO APLICAÇÕES | C37: Provento | D37: ='HOLERITE AGO.26'!C19
A38: AGNOR | B38: INCENTIVO VITAMINAS | C38: Provento | D38: ='HOLERITE AGO.26'!C20
A39: AGNOR | B39: OUTROS INCENTIVOS | C39: Provento | D39: ='HOLERITE AGO.26'!C21
A40: AGNOR | B40: TOTAL DE PROVENTOS | C40: Subtotal | D40: ='HOLERITE AGO.26'!C22
A41: AGNOR | B41: ADIANTAMENTO / VALES | C41: Desconto | D41: ='HOLERITE AGO.26'!C24
A42: AGNOR | B42: ADIANT. VALES INCENT. E APLIC. | C42: Desconto | D42: ='HOLERITE AGO.26'!C25
...

Sheet GANHOS DO COLABORADOR
A1: DEMONSTRATIVO DE GANHOS DO COLABORADOR
A2: Competência AGOSTO/2026 · Pagamento em 05/09/2026 · Farmácia Tropical Multi Econômica
B4: Escolha o colaborador: | C4: DEAN | D4: Troque o nome aqui e a tabela abaixo muda sozinha — é o relatório para mandar para cada um.
B6: PROVENTOS
B7: Salário base | C7: =IFERROR(INDEX('HOLERITE AGO.26'!$B$6:$I$6,1,MATCH($C$4,'HOLERITE AGO.26'!$B$4:$I$4,0)),0)
B8: Adicional noturno | C8: =IFERROR(INDEX('HOLERITE AGO.26'!$B$7:$I$7,1,MATCH($C$4,'HOLERITE AGO.26'!$B$4:$I$4,0)),0)
B9: Horas extras | C9: =IFERROR(INDEX('HOLERITE AGO.26'!$B$8:$I$8,1,MATCH($C$4,'HOLERITE AGO.26'!$B$4:$I$4,0)),0)
B10: Comissão sobre vendas | C10: =IFERROR(INDEX('HOLERITE AGO.26'!$B$11:$I$11,1,MATCH($C$4,'HOLERITE AGO.26'!$B$4:$I$4,0)),0)
B11: Repouso remunerado / DSR | C11: =IFERROR(INDEX('HOLERITE AGO.26'!$B$12:$I$12,1,MATCH($C$4,'HOLERITE AGO.26'!$B$4:$I$4,0)),0)
B12: Auxílio gerência | C12: =IFERROR(INDEX('HOLERITE AGO.26'!$B$13:$I$13,1,MATCH($C$4,'HOLERITE AGO.26'!$B$4:$I$4,0)),0)
B13: Adicional prêmio meta caixa | C13: =IFERROR(INDEX('HOLERITE AGO.26'!$B$14:$I$14,1,MATCH($C$4,'HOLERITE AGO.26'!$B$4:$I$4,0)),0)
B14: Prêmio cota geral | C14: =IFERROR(INDEX('HOLERITE AGO.26'!$B$15:$I$15,1,MATCH($C$4,'HOLERITE AGO.26'!$B$4:$I$4,0)),0)
B15: Prêmio pré-vencidos | C15: =IFERROR(INDEX('HOLERITE AGO.26'!$B$16:$I$16,1,MATCH($C$4,'HOLERITE AGO.26'!$B$4:$I$4,0)),0)
B16: Férias | C16: =IFERROR(INDEX('HOLERITE AGO.26'!$B$17:$I$17,1,MATCH($C$4,'HOLERITE AGO.26'!$B$4:$I$4,0)),0)
B17: 1/3 constitucional de férias | C17: =IFERROR(INDEX('HOLERITE AGO.26'!$B$18:$I$18,1,MATCH($C$4,'HOLERITE AGO.26'!$B$4:$I$4,0)),0)
B18: Incentivo aplicações | C18: =IFERROR(INDEX('HOLERITE AGO.26'!$B$19:$I$19,1,MATCH($C$4,'HOLERITE AGO.26'!$B$4:$I$4,0)),0)
B19: Incentivo vitaminas | C19: =IFERROR(INDEX('HOLERITE AGO.26'!$B$20:$I$20,1,MATCH($C$4,'HOLERITE AGO.26'!$B$4:$I$4,0)),0)
B20: Outros incentivos | C20: =IFERROR(INDEX('HOLERITE AGO.26'!$B$21:$I$21,1,MATCH($C$4,'HOLERITE AGO.26'!$B$4:$I$4,0)),0)
B21: TOTAL DE PROVENTOS | C21: =IFERROR(INDEX('HOLERITE AGO.26'!$B$22:$I$22,1,MATCH($C$4,'HOLERITE AGO.26'!$B$4:$I$4,0)),0)
B22: DESCONTOS
B23: Adiantamento / vales | C23: =IFERROR(INDEX('HOLERITE AGO.26'!$B$24:$I$24,1,MATCH($C$4,'HOLERITE AGO.26'!$B$4:$I$4,0)),0)
B24: Adiantamento de incentivos e aplicações | C24: =IFERROR(INDEX('HOLERITE AGO.26'!$B$25:$I$25,1,MATCH($C$4,'HOLERITE AGO.26'!$B$4:$I$4,0)),0)
B25: Convênio | C25: =IFERROR(INDEX('HOLERITE AGO.26'!$B$26:$I$26,1,MATCH($C$4,'HOLERITE AGO.26'!$B$4:$I$4,0)),0)
B26: Faltas / atrasos | C26: =IFERROR(INDEX('HOLERITE AGO.26'!$B$27:$I$27,1,MATCH($C$4,'HOLERITE AGO.26'!$B$4:$I$4,0)),0)
B27: Vale transporte 6% | C27: =IFERROR(INDEX('HOLERITE AGO.26'!$B$28:$I$28,1,MATCH($C$4,'HOLERITE AGO.26'!$B$4:$I$4,0)),0)
B28: INSS | C28: =IFERROR(INDEX('HOLERITE AGO.26'!$B$29:$I$29,1,MATCH($C$4,'HOLERITE AGO.26'!$B$4:$I$4,0)),0)
B29: IRRF | C29: =IFERROR(INDEX('HOLERITE AGO.26'!$B$30:$I$30,1,MATCH($C$4,'HOLERITE AGO.26'!$B$4:$I$4,0)),0)
B30: TOTAL DE DESCONTOS | C30: =IFERROR(INDEX('HOLERITE AGO.26'!$B$31:$I$31,1,MATCH($C$4,'HOLERITE AGO.26'!$B$4:$I$4,0)),0)
B31: LÍQUIDO
B32: LÍQUIDO A RECEBER EM 05/09/2026 | C32: =IFERROR(INDEX('HOLERITE AGO.26'!$B$33:$I$33,1,MATCH($C$4,'HOLERITE AGO.26'!$B$4:$I$4,0)),0)
B34: Vendas do colaborador no mês (InovaFarma):
B35: Venda bruta | C35: =IFERROR(INDEX('BASE INOVAFARMA AGO.26'!$C$5:$C$12,MATCH($C$4,'BASE INOVAFARMA AGO.26'!$B$5:$B$12,0)),0)
B36: Descontos concedidos | C36: =IFERROR(INDEX('BASE INOVAFARMA AGO.26'!$D$5:$D$12,MATCH($C$4,'BASE INOVAFARMA AGO.26'!$B$5:$B$12,0)),0)
B37: Venda líquida | C37: =IFERROR(INDEX('BASE INOVAFARMA AGO.26'!$E$5:$E$12,MATCH($C$4,'BASE INOVAFARMA AGO.26'!$B$5:$B$12,0)),0)
B38: Comissão apurada | C38: =IFERROR(INDEX('BASE INOVAFARMA AGO.26'!$F$5:$F$12,MATCH($C$4,'BASE INOVAFARMA AGO.26'!$B$5:$B$12,0)),0)
B39: Total de incentivos | C39: =IFERROR(INDEX('BASE INOVAFARMA AGO.26'!$J$5:$J$12,MATCH($C$4,'BASE INOVAFARMA AGO.26'!$B$5:$B$12,0)),0)
B41: A comissão apurada acima é a apuração do sistema. O que entra na folha é a linha "Comissão sobre vendas" — pode ser diferente (valor fixo acordado, PDV antigos ou quem não recebe comissão).
B42: Os valores de INSS e IRRF são calculados pela contabilidade e só aparecem aqui depois de preenchidos na aba HOLERITE AGO.26.
B43: Para mandar para o colaborador: selecione o nome acima e imprima esta aba em PDF (ou tire um print).
B44: Na aba LISTA CONTABILIDADE também dá para filtrar por FUNCIONÁRIO e ver só os lançamentos de uma pessoa.

Sheet PONTO AGO.26
A1: APONTAMENTO DO PONTO — AGOSTO/2026
A2: Horas extras, adicional noturno e feriado trabalhado · alimenta as rubricas da aba HOLERITE AGO.26
A4: FUNCIONÁRIO | B4: OCORRÊNCIA | C4: QTDE | D4: UNIDADE | E4: SALÁRIO BASE | F4: VALOR UNITÁRIO | G4: TOTAL | H4: RUBRICA DESTINO | I4: OBSERVAÇÃO
A5: EDEY | B5: Horas extras 50% | C5: 24 | D5: horas | E5: =IFERROR(INDEX('HOLERITE AGO.26'!$B$6:$I$6,1,MATCH(A5,'HOLERITE AGO.26'!$B$4:$I$4,0)),0) | F5: =ROUND(E5/PARÂMETROS!$B$20*(1+PARÂMETROS!$B$21),4) | G5: =ROUND(C5*F5,2) | H5: HORAS EXTRAS | I5: 24 horas extras normais em agosto/2026.
A6: EDEY | B6: Adicional noturno (valor fixo) | C6: 1 | D6: valor | E6: =IFERROR(INDEX('HOLERITE AGO.26'!$B$6:$I$6,1,MATCH(A6,'HOLERITE AGO.26'!$B$4:$I$4,0)),0) | F6: 350 | G6: =ROUND(C6*F6,2) | H6: ADICIONAL NOTURNO | I6: Adicional noturno lançado como valor fixo desde jul/26 — CONFERIR com o apontamento do ponto.
A7: NATI | B7: Adicional noturno | C7: 17 | D7: horas | E7: =IFERROR(INDEX('HOLERITE AGO.26'!$B$6:$I$6,1,MATCH(A7,'HOLERITE AGO.26'!$B$4:$I$4,0)),0) | F7: =ROUND(E7/PARÂMETROS!$B$20*PARÂMETROS!$B$22,4) | G7: =ROUND(C7*F7,2) | H7: ADICIONAL NOTURNO | I7: 17 horas noturnas.
A8: NATI | B8: Feriado trabalhado (dobra) | C8: 1 | D8: dias | E8: =IFERROR(INDEX('HOLERITE AGO.26'!$B$6:$I$6,1,MATCH(A8,'HOLERITE AGO.26'!$B$4:$I$4,0)),0) | F8: =ROUND(E8/PARÂMETROS!$B$23,2) | G8: =ROUND(C8*F8,2) | H8: HORAS EXTRAS | I8: Feriado de 15/08/2026 trabalhado, sem folga compensatória — pago em dobro (1 dia a mais).
A9: CAMILA | B9: Feriado trabalhado (dobra) | C9: 1 | D9: dias | E9: =IFERROR(INDEX('HOLERITE AGO.26'!$B$6:$I$6,1,MATCH(A9,'HOLERITE AGO.26'!$B$4:$I$4,0)),0) | F9: =ROUND(E9/PARÂMETROS!$B$23,2) | G9: =ROUND(C9*F9,2) | H9: HORAS EXTRAS | I9: Dia 15/08/2026 (feriado) trabalhado.
A10: SARA | B10: Feriado trabalhado (dobra) | C10: 1 | D10: dias | E10: =IFERROR(INDEX('HOLERITE AGO.26'!$B$6:$I$6,1,MATCH(A10,'HOLERITE AGO.26'!$B$4:$I$4,0)),0) | F10: =ROUND(E10/PARÂMETROS!$B$23,2) | G10: =ROUND(C10*F10,2) | H10: HORAS EXTRAS | I10: Dia 15/08/2026 (feriado) trabalhado.
A11: VALÉRIA | B11: Feriado trabalhado (dobra) | C11: 1 | D11: dias | E11: =IFERROR(INDEX('HOLERITE AGO.26'!$B$6:$I$6,1,MATCH(A11,'HOLERITE AGO.26'!$B$4:$I$4,0)),0) | F11: =ROUND(E11/PARÂMETROS!$B$23,2) | G11: =ROUND(C11*F11,2) | H11: HORAS EXTRAS | I11: Dia 15/08/2026 (feriado) trabalhado.
A12: VALÉRIA | B12: Adicional noturno | D12: horas | E12: =IFERROR(INDEX('HOLERITE AGO.26'!$B$6:$I$6,1,MATCH(A12,'HOLERITE AGO.26'!$B$4:$I$4,0)),0) | F12: =ROUND(E12/PARÂMETROS!$B$20*PARÂMETROS!$B$22,4) | G12: =ROUND(C12*F12,2) | H12: ADICIONAL NOTURNO | I12: 2 madrugadas trabalhadas, com folga normal no dia seguinte — cabe só o adicional noturno. INFORMAR o total de horas noturnas das 2 madrugadas.
A13: AGNOR | B13: Adicional noturno | D13: horas | E13: =IFERROR(INDEX('HOLERITE AGO.26'!$B$6:$I$6,1,MATCH(A13,'HOLERITE AGO.26'!$B$4:$I$4,0)),0) | F13: =ROUND(E13/PARÂMETROS!$B$20*PARÂMETROS!$B$22,4) | G13: =ROUND(C13*F13,2) | H13: ADICIONAL NOTURNO | I13: 3 madrugadas trabalhadas, com folga normal — cabe só o adicional noturno. INFORMAR o total de horas noturnas das 3 madrugadas.
A14: DEAN | B14: Feriado com folga compensatória | C14: 1 | D14: dias | E14: =IFERROR(INDEX('HOLERITE AGO.26'!$B$6:$I$6,1,MATCH(A14,'HOLERITE AGO.26'!$B$4:$I$4,0)),0) | F14: 0 | G14: =ROUND(C14*F14,2) | H14: — | I14: Dia 15/08/2026 trabalhado, com folga compensatória — nada a pagar, registro apenas.
E15: =IFERROR(INDEX('HOLERITE AGO.26'!$B$6:$I$6,1,MATCH(A15,'HOLERITE AGO.26'!$B$4:$I$4,0)),0) | G15: =ROUND(C15*F15,2)
E16: =IFERROR(INDEX('HOLERITE AGO.26'!$B$6:$I$6,1,MATCH(A16,'HOLERITE AGO.26'!$B$4:$I$4,0)),0) | G16: =ROUND(C16*F16,2)
E17: =IFERROR(INDEX('HOLERITE AGO.26'!$B$6:$I$6,1,MATCH(A17,'HOLERITE AGO.26'!$B$4:$I$4,0)),0) | G17: =ROUND(C17*F17,2)
E18: =IFERROR(INDEX('HOLERITE AGO.26'!$B$6:$I$6,1,MATCH(A18,'HOLERITE AGO.26'!$B$4:$I$4,0)),0) | G18: =ROUND(C18*F18,2)
E19: =IFERROR(INDEX('HOLERITE AGO.26'!$B$6:$I$6,1,MATCH(A19,'HOLERITE AGO.26'!$B$4:$I$4,0)),0) | G19: =ROUND(C19*F19,2)
E20: =IFERROR(INDEX('HOLERITE AGO.26'!$B$6:$I$6,1,MATCH(A20,'HOLERITE AGO.26'!$B$4:$I$4,0)),0) | G20: =ROUND(C20*F20,2)
B21: TOTAL | G21: =SUM(G5:G20)
A23: Salário-hora = salário base ÷ 220. Hora extra = salário-hora × 1,5. Adicional noturno = salário-hora × 20%. Feriado trabalhado sem folga = 1 salário-dia a mais (salário base ÷ 30).
A24: Confira: 40 horas extras dão R$ 442,09 e 24 horas dão R$ 265,25 no salário de R$ 1.621,00 — é a mesma conta usada na planilha de julho.
A25: As linhas em branco no fim da tabela são para acrescentar outras ocorrências: preencha funcionário, ocorrência, quantidade, valor unitário e a rubrica de destino (HORAS EXTRAS ou ADICIONAL NOTURNO).
A26: Os totais desta aba entram sozinhos nas linhas HORAS EXTRAS e ADICIONAL NOTURNO da aba HOLERITE AGO.26 — não digite nada por cima lá.
